[2025-10-04T02:51:47.379+0000] {scheduler_job_runner.py:1586} WARNING - Marking task instance <TaskInstance: coms_end_to_end_etl.process_raw_customers_csv scheduled__2025-10-03T00:00:00+00:00 [queued]> stuck in queued as failed. If the task instance has available retries, it will be retried.
[2025-10-04T02:51:48.384+0000] {scheduler_job_runner.py:781} ERROR - Executor reports task instance <TaskInstance: coms_end_to_end_etl.process_raw_customers_csv scheduled__2025-10-03T00:00:00+00:00 [queued]> finished (failed) although the task says it's queued. (Info: None) Was the task killed externally?
