[2025-10-03T15:20:44.101+0000] {scheduler_job_runner.py:1586} WARNING - Marking task instance <TaskInstance: coms_end_to_end_etl.process_raw_order_items_csv manual__2025-10-03T15:05:25.670723+00:00 [queued]> stuck in queued as failed. If the task instance has available retries, it will be retried.
[2025-10-03T15:20:44.335+0000] {scheduler_job_runner.py:781} ERROR - Executor reports task instance <TaskInstance: coms_end_to_end_etl.process_raw_order_items_csv manual__2025-10-03T15:05:25.670723+00:00 [queued]> finished (failed) although the task says it's queued. (Info: None) Was the task killed externally?
